Workbook

Sheet Cuadro de mando
B2: Precios de la energía en España
B3: Informe semanal · fecha de referencia 27/10/2026 · última actualización 2026-10-27 12:07 UTC · precios con impuestos salvo los mercados mayoristas
C5: 1. OMIE · mayorista, sin impuestos | D5: 2. MIBGAS · mayorista, sin impuestos | G5: 3. Gasóleo A · con impuestos | J5: 4. PVPC 2.0TD · con impuestos
C6: 0.15221557 | D6: 0.090581429 | G6: 0.183776 | J6: 0.25507757
C7: Semana: ▼ -8,6 % | D7: Semana: ▲ +5,1 % | G7: Semana: ■ -0,0 % | J7: Semana: ▲ +1,0 %
C8: Un año: ▲ +128,5 % | D8: Un año: ▲ +189,5 % | G8: Un año: ▲ +35,2 % | J8: Un año: ▲ +39,6 %
C10: OMIE · dato del 27/10/2026 | D10: MIBGAS · dato del 26/10/2026 | G10: Comisión Europea (WOB) · dato del 19/10/2026 | J10: REE/ESIOS · dato del 27/10/2026
C12: 5. TUR 2 · con impuestos | D12: 6. Gasóleo C · con impuestos | G12: 7. Butano · con impuestos | J12: 8. Pellet saco 15 kg · con impuestos
C13: 0.070629 | D13: 0.147989 | G13: 0.118405 | J13: 0.082222
C14: Semana: ■ 0,0 % | D14: Semana: ▲ +5,3 % | G14: Semana: ■ 0,0 % | J14: Semana: ■ 0,0 %
C15: Un año: ▲ +16,5 % | D15: Un año: ▲ +74,9 % | G15: Un año: ▲ +15,8 % | J15: Un año: ▲ +11,5 %
J16: Pellet granel: 0,077 €/kWh (■ 0,0 % semana, ▲ +13,1 % año)
C17: BOE (DGPEM) · dato del 01/10/2026 | D17: Comisión Europea (WOB) · dato del 19/10/2026 | G17: BOE (DGPEM) · dato del 15/09/2026 | J17: AVEBIOM · dato del 01/07/2026
B19: Tabla de indicadores
B20: N.º | C20: Indicador | D20: Precio actual (€/kWh) | E20: Var. semanal (%) | F20: Var. interanual (%) | G20: Fecha del dato | H20: Valor original | I20: Unidad original | J20: Fuente | K20: Impuestos | L20: Estado
B21: 1 | C21: Electricidad: precio del mercado diario OMIE, España | D21: 0.15221557 | E21: -0.085609564 | F21: 1.2847546 | G21: 2026-10-27 | H21: 206.8894 | I21: €/MWh | J21: OMIE | K21: sin (mayorista) | L21: actualizado
B22: 2 | C22: Gas natural: MIBGAS-ES Index | D22: 0.090581429 | E22: 0.051316488 | F22: 1.8947681 | G22: 2026-10-26 | H22: 94.69 | I22: €/MWh | J22: MIBGAS | K22: sin (mayorista) | L22: actualizado
B23: 3 | C23: Gasóleo de automoción: precio medio en España | D23: 0.183776 | E23: -8.1614442e-05 | F23: 0.35248749 | G23: 2026-10-19 | H23: 1.88922 | I23: €/l | J23: Comisión Europea (WOB) | K23: con | L23: sin actualización en el periodo
B24: 4 | C24: Electricidad PVPC: término de energía, tarifa 2.0TD (Península) | D24: 0.25507757 | E24: 0.01020306 | F24: 0.39568821 | G24: 2026-10-27 | H24: 231.6446 | I24: €/MWh | J24: REE/ESIOS | K24: con | L24: actualizado
B25: 5 | C25: Gas natural TUR 2: término variable | D25: 0.070629 | E25: 0 | F25: 0.16537967 | G25: 2026-10-01 | H25: 5.042762 | I25: c€/kWh (PCS) | J25: BOE (DGPEM) | K25: con | L25: sin actualización en el periodo
B26: 6 | C26: Gasóleo de calefacción: precio medio en España | D26: 0.147989 | E26: 0.052605749 | F26: 0.74940303 | G26: 2026-10-19 | H26: 1.52133 | I26: €/l | J26: Comisión Europea (WOB) | K26: con | L26: sin actualización en el periodo
B27: 7 | C27: Butano: bombona regulada de 12,5 kg | D27: 0.118405 | E27: 0 | F27: 0.15797246 | G27: 2026-09-15 | H27: 123.4447 | I27: c€/kg (antes de impuestos) | J27: BOE (DGPEM) | K27: con | L27: sin actualización en el periodo
B28: 8 | C28: Pellet: precio medio en España del saco de 15 kg | D28: 0.082222 | E28: 0 | F28: 0.11487458 | G28: 2026-07-01 | H28: 5.92 | I28: €/saco | J28: AVEBIOM | K28: con | L28: sin actualización en el periodo
B29: 8 | C29: Pellet: precio medio en España a granel en volquete | D29: 0.077133 | E29: 0 | F29: 0.13091608 | G29: 2026-07-01 | H29: 370.24 | I29: €/t | J29: AVEBIOM | K29: con | L29: sin actualización en el periodo
B31: Claves de la semana (generadas a partir de los datos)
B32: • Variaciones semanales de al menos un 1 %: OMIE -8,6 %; Gasóleo C +5,3 %; MIBGAS +5,1 %; PVPC 2.0TD +1,0 %.
B33: • Sin cambios apreciables en la semana (menos de un 1 %): Gasóleo A, TUR 2, Butano, Pellet saco 15 kg, Pellet granel.
B34: • Respecto a hace un año, suben OMIE (+128,5 %), MIBGAS (+189,5 %), Gasóleo A (+35,2 %), PVPC 2.0TD (+39,6 %), TUR 2 (+16,5 %), Gasóleo C (+74,9 %), Butano (+15,8 %), Pellet saco 15 kg (+11,5 %), Pellet granel (+13,1 %).
B35: • Precio por kWh de energía final, con impuestos, de menor a mayor: TUR 2 0,071 €/kWh; Pellet granel 0,077 €/kWh; Pellet saco 15 kg 0,082 €/kWh; Butano 0,118 €/kWh; Gasóleo C 0,148 €/kWh; Gasóleo A 0,184 €/kWh; PVPC 2.0TD 0,255 €/kWh. El más caro (PVPC 2.0TD) cuesta 3,6 veces el más barato (TUR 2).
B36: • Precios mayoristas, sin impuestos: OMIE 0,1522 €/kWh; MIBGAS 0,0906 €/kWh.
B38: Criterios: precio actual = media de 7 días (OMIE, MIBGAS, PVPC), última semana (gasóleos) o valor vigente (TUR 2, butano, pellet); variaciones frente al periodo anterior y frente a hace un año; nada se estima (n. d. = no disponible).
B40: Ranking: coste por kWh de la energía final, con impuestos (de menor a mayor)
C41: Indicador | D41: €/kWh
C42: TUR 2 | D42: 0.070629
C43: Pellet granel | D43: 0.077133
C44: Pellet saco 15 kg | D44: 0.082222
C45: Butano | D45: 0.118405
C46: Gasóleo C | D46: 0.147989
C47: Gasóleo A | D47: 0.183776
C48: PVPC 2.0TD | D48: 0.25507757

Sheet Anual
A1: Año | B1: OMIE (sin imp.) | C1: MIBGAS (sin imp.) | D1: Gasóleo A | E1: PVPC 2.0TD | F1: TUR 2 | G1: Gasóleo C | H1: Butano | I1: Pellet saco 15 kg | J1: Pellet granel
A2: 2020 | B2: 0.033958917 | C2: 0.010212917 | D2: 0.1043725 | F2: 0.0575145 | G2: 0.055254917 | H2: 0.081292333 | I2: 0.060972 | J2: 0.050056
A3: 2021 | B3: 0.11139133 | C3: 0.047298667 | D3: 0.12080808 | F3: 0.05812675 | G3: 0.070687083 | H3: 0.093365583 | I3: 0.060278 | J3: 0.05134
A4: 2022 | B4: 0.1676545 | C4: 0.098655667 | D4: 0.17500292 | E4: 0.31041608 | F4: 0.07076575 | G4: 0.12557575 | H4: 0.118568 | I4: 0.090694 | J4: 0.084975
A5: 2023 | B5: 0.0874045 | C5: 0.0390675 | D5: 0.15186558 | E5: 0.15560342 | F5: 0.0588715 | G5: 0.1025375 | H5: 0.10067475 | I5: 0.08625 | J5: 0.075281
A6: 2024 | B6: 0.062893917 | C6: 0.034666 | D6: 0.14308992 | E6: 0.15014225 | F6: 0.06187425 | G6: 0.095686667 | H6: 0.100759 | I6: 0.07263925 | J6: 0.067249
A7: 2025 | B7: 0.065400167 | C7: 0.03599025 | D7: 0.13872692 | E7: 0.173742 | F7: 0.064138 | G7: 0.089194583 | H7: 0.106231 | I7: 0.0715625 | J7: 0.06549875
A8: 2026 | B8: 0.0820979 | C8: 0.0530572 | D8: 0.1636491 | E8: 0.1828093 | F8: 0.0549546 | G8: 0.1163286 | H8: 0.1043719 | I8: 0.078148 | J8: 0.074261667
A10: Media anual en €/kWh de cada serie (media de sus medias mensuales). Solo años completos; el año en curso usa los meses disponibles. Vacío = falta algún mes.

Sheet Mensual
A1: Mes | B1: OMIE (€/kWh, sin imp.) | C1: OMIE (€/MWh) | D1: MIBGAS (€/kWh, sin imp.) | E1: MIBGAS (€/MWh) | F1: Gasóleo A (€/kWh, con imp.) | G1: Gasóleo A (€/l) | H1: PVPC 2.0TD (€/kWh, con imp.) | I1: PVPC 2.0TD (€/MWh) | J1: TUR 2 (€/kWh, con imp.) | K1: TUR 2 (c€/kWh (PCS)) | L1: Gasóleo C (€/kWh, con imp.) | M1: Gasóleo C (€/l) | N1: Butano (€/kWh, con imp.) | O1: Butano (c€/kg (antes de impuestos)) | P1: Pellet saco 15 kg (€/kWh, con imp.) | Q1: Pellet saco 15 kg (€/saco) | R1: Pellet granel (€/kWh, con imp.) | S1: Pellet granel (€/t)
A2: 2020-01 | B2: 0.041101 | C2: 41.101397 | D2: 0.011879 | E2: 11.879355 | F2: 0.121196 | G2: 1.245892 | J2: 0.060353 | K2: 4.275044 | L2: 0.076468 | M2: 0.786088 | N2: 0.081509 | O2: 84.252748 | P2: 0.060972 | Q2: 4.39 | R2: 0.050056 | S2: 240.27
A3: 2020-02 | B3: 0.035869 | C3: 35.868697 | D3: 0.009817 | E3: 9.817241 | F3: 0.11745 | G3: 1.207385 | J3: 0.060353 | K3: 4.275044 | L3: 0.069908 | M3: 0.718655 | N3: 0.084047 | O3: 86.9232 | P3: 0.060972 | Q3: 4.39 | R3: 0.050056 | S3: 240.27
A4: 2020-03 | B4: 0.027729 | C4: 27.72879 | D4: 0.008563 | E4: 8.562903 | F4: 0.109557 | G4: 1.126248 | J4: 0.060353 | K4: 4.275044 | L4: 0.059326 | M4: 0.609866 | N4: 0.084047 | O4: 86.9232 | P4: 0.060972 | Q4: 4.39 | R4: 0.050056 | S4: 240.27
A5: 2020-04 | B5: 0.017653 | C5: 17.652967 | D5: 0.007482 | E5: 7.481667 | F5: 0.099217 | G5: 1.019947 | J5: 0.060353 | K5: 4.275044 | L5: 0.048452 | M5: 0.498087 | N5: 0.084047 | O5: 86.9232 | P5: 0.060972 | Q5: 4.39 | R5: 0.050056 | S5: 240.27
A6: 2020-05 | B6: 0.021255 | C6: 21.2549 | D6: 0.005331 | E6: 5.330645 | F6: 0.095941 | G6: 0.98627 | J6: 0.060353 | K6: 4.275044 | L6: 0.045096 | M6: 0.463583 | N6: 0.084047 | O6: 86.9232 | P6: 0.060972 | Q6: 4.39 | R6: 0.050056 | S6: 240.27
A7: 2020-06 | B7: 0.030618 | C7: 30.617753 | D7: 0.006426 | E7: 6.425667 | F7: 0.09917 | G7: 1.019468 | J7: 0.060353 | K7: 4.275044 | L7: 0.050138 | M7: 0.515414 | N7: 0.084047 | O7: 86.9232 | P7: 0.060972 | Q7: 4.39 | R7: 0.050056 | S7: 240.27
A8: 2020-07 | B8: 0.034636 | C8: 34.63601 | D8: 0.006435 | E8: 6.434516 | F8: 0.102768 | G8: 1.056453 | J8: 0.056262 | K8: 3.9694 | L8: 0.053658 | M8: 0.551602 | N8: 0.082581 | O8: 85.381 | P8: 0.060972 | Q8: 4.39 | R8: 0.050056 | S8: 240.27
A9: 2020-08 | B9: 0.036198 | C9: 36.198019 | D9: 0.009187 | E9: 9.186774 | F9: 0.103165 | G9: 1.060542 | J9: 0.056262 | K9: 3.9694 | L9: 0.053266 | M9: 0.54758 | N9: 0.079916 | O9: 82.577 | P9: 0.060972 | Q9: 4.39 | R9: 0.050056 | S9: 240.27
A10: 2020-09 | B10: 0.041957 | C10: 41.957077 | D10: 0.01131 | E10: 11.31 | F10: 0.101148 | G10: 1.039802 | J10: 0.056262 | K10: 3.9694 | L10: 0.05043 | M10: 0.518423 | N10: 0.077823 | O10: 80.374973 | P10: 0.060972 | Q10: 4.39 | R10: 0.050056 | S10: 240.27
A11: 2020-10 | B11: 0.03659 | C11: 36.589939 | D11: 0.013441 | E11: 13.440645 | F11: 0.100056 | G11: 1.028575 | J11: 0.05309 | K11: 3.73238 | L11: 0.050225 | M11: 0.51631 | N11: 0.075992 | O11: 78.4482 | P11: 0.060972 | Q11: 4.39 | R11: 0.050056 | S11: 240.27
A12: 2020-11 | B12: 0.041936 | C12: 41.936147 | D12: 0.0145 | E12: 14.5 | F12: 0.099839 | G12: 1.026346 | J12: 0.05309 | K12: 3.73238 | L12: 0.050907 | M12: 0.523322 | N12: 0.077732 | O12: 80.278653 | P12: 0.060972 | Q12: 4.39 | R12: 0.050056 | S12: 240.27
A13: 2020-12 | B13: 0.041965 | C13: 41.965274 | D13: 0.018184 | E13: 18.183548 | F13: 0.102963 | G13: 1.058463 | J13: 0.05309 | K13: 3.73238 | L13: 0.055185 | M13: 0.5673 | N13: 0.07972 | O13: 82.3706 | P13: 0.060972 | Q13: 4.39 | R13: 0.050056 | S13: 240.27
... A18: 2021-05 | B18: 0.067125 | C18: 67.124906 | D18: 0.024697 | E18: 24.697419 | F18: 0.117104 | G18: 1.203832 | J18: 0.057157 | K18: 4.036244 | L18: 0.066799 | M18: 0.68669 | N18: 0.089694 | O18: 92.864239 | P18: 0.060278 | Q18: 4.34 | R18: 0.05134 | S18: 246.43
A19: 2021-06 | B19: 0.0833 | C19: 83.299837 | D19: 0.028666 | E19: 28.665667 | F19: 0.12008 | G19: 1.234422 | H19: 0.186862 | I19: 149.09967 | J19: 0.057157 | K19: 4.036244 | L19: 0.069519 | M19: 0.714655 | N19: 0.092061 | O19: 95.3543 | P19: 0.060278 | Q19: 4.34 | R19: 0.05134 | S19: 246.43
A20: 2021-07 | B20: 0.092415 | C20: 92.415384 | D20: 0.036474 | E20: 36.473548 | F20: 0.122754 | G20: 1.261907 | H20: 0.182395 | I20: 157.74819 | J20: 0.059814 | K20: 4.234768 | L20: 0.071553 | M20: 0.735565 | N20: 0.093815 | O20: 97.199861 | P20: 0.060278 | Q20: 4.34 | R20: 0.05134 | S20: 246.43
A21: 2021-08 | B21: 0.105941 | C21: 105.9407 | D21: 0.044605 | E21: 44.604516 | F21: 0.123069 | G21: 1.265144 | H21: 0.20305 | I21: 175.61211 | J21: 0.059814 | K21: 4.234768 | L21: 0.071757 | M21: 0.73766 | N21: 0.096593 | O21: 100.122 | P21: 0.060278 | Q21: 4.34 | R21: 0.05134 | S21: 246.43
A22: 2021-09 | B22: 0.156144 | C22: 156.14447 | D22: 0.064683 | E22: 64.682667 | F22: 0.124203 | G22: 1.276805 | H22: 0.246414 | I22: 217.90283 | J22: 0.059814 | K22: 4.234768 | L22: 0.073308 | M22: 0.75361 | N22: 0.098179 | O22: 101.7907 | P22: 0.060278 | Q22: 4.34 | R22: 0.05134 | S22: 246.43
A23: 2021-10 | B23: 0.200057 | C23: 200.05757 | D23: 0.089705 | E23: 89.704839 | F23: 0.130744 | G23: 1.344045 | H23: 0.285797 | I23: 258.49419 | J23: 0.058379 | K23: 4.127554 | L23: 0.080606 | M23: 0.82863 | N23: 0.101351 | O23: 105.1281 | P23: 0.060278 | Q23: 4.34 | R23: 0.05134 | S23: 246.43
A24: 2021-11 | B24: 0.193431 | C24: 193.43079 | D24: 0.083105 | E24: 83.105333 | F24: 0.134418 | G24: 1.381812 | H24: 0.278164 | I24: 251.60229 | J24: 0.058379 | K24: 4.127554 | L24: 0.08317 | M24: 0.854986 | N24: 0.103849 | O24: 107.7563 | P24: 0.060278 | Q24: 4.34 | R24: 0.05134 | S24: 246.43
A25: 2021-12 | B25: 0.239165 | C25: 239.16496 | D25: 0.111953 | E25: 111.9529 | F25: 0.131186 | G25: 1.348593 | H25: 0.345275 | I25: 312.29182 | J25: 0.058379 | K25: 4.127554 | L25: 0.079591 | M25: 0.818193 | N25: 0.106347 | O25: 110.3845 | P25: 0.060278 | Q25: 4.34 | R25: 0.05134 | S25: 246.43
A26: 2022-01 | B26: 0.201718 | C26: 201.71762 | D26: 0.082843 | E26: 82.842903 | F26: 0.134506 | G26: 1.382728 | H26: 0.31603 | I26: 285.86005 | J26: 0.063634 | K26: 4.520114 | L26: 0.085248 | M26: 0.876348 | N26: 0.108716 | O26: 112.87704 | P26: 0.090694 | Q26: 6.53 | R26: 0.084975 | S26: 407.88
A27: 2022-02 | B27: 0.200219 | C27: 200.21925 | D27: 0.081255 | E27: 81.255 | F27: 0.143077 | G27: 1.470835 | H27: 0.316517 | I27: 286.30842 | J27: 0.063634 | K27: 4.520114 | L27: 0.094202 | M27: 0.968397 | N27: 0.111593 | O27: 115.9037 | P27: 0.090694 | Q27: 6.53 | R27: 0.084975 | S27: 407.88
A28: 2022-03 | B28: 0.283304 | C28: 283.30356 | D28: 0.125681 | E28: 125.68097 | F28: 0.171041 | G28: 1.758297 | H28: 0.428496 | I28: 387.60415 | J28: 0.063634 | K28: 4.520114 | L28: 0.128854 | M28: 1.324612 | N28: 0.114614 | O28: 119.08171 | P28: 0.090694 | Q28: 6.53 | R28: 0.084975 | S28: 407.88
A29: 2022-04 | B29: 0.191517 | C29: 191.51655 | D29: 0.090125 | E29: 90.125 | F29: 0.178609 | G29: 1.836103 | H29: 0.297007 | I29: 268.63353 | J29: 0.069648 | K29: 4.969479 | L29: 0.129845 | M29: 1.334803 | N29: 0.117102 | O29: 121.6989 | P29: 0.090694 | Q29: 6.53 | R29: 0.084975 | S29: 407.88
A30: 2022-05 | B30: 0.187126 | C30: 187.12602 | D30: 0.076205 | E30: 76.205161 | F30: 0.182696 | G30: 1.878118 | H30: 0.287361 | I30: 259.93356 | J30: 0.069648 | K30: 4.969479 | L30: 0.132373 | M30: 1.360798 | N30: 0.119901 | O30: 124.64321 | P30: 0.090694 | Q30: 6.53 | R30: 0.084975 | S30: 407.88
... A82: 2026-09 | B82: 0.143254 | C82: 143.25404 | D82: 0.07713 | E82: 77.129667 | F82: 0.181955 | G82: 1.870492 | H82: 0.233991 | I82: 183.97466 | J82: 0.057024 | K82: 4.119908 | L82: 0.141957 | M82: 1.45932 | N82: 0.115465 | O82: 120.70149 | P82: 0.082222 | Q82: 5.92 | R82: 0.077133 | S82: 370.24
A83: 2026-10 | B83: 0.158678 | C83: 158.67789 | D83: 0.082779 | E83: 82.779231 | F83: 0.184703 | G83: 1.898743 | H83: 0.248657 | I83: 195.50572 | J83: 0.070629 | K83: 5.042762 | L83: 0.144681 | M83: 1.487323 | N83: 0.118405 | O83: 123.4447

Sheet Gráficos
A1: Gráficos vinculados a las hojas «Mensual» y «Anual»: se actualizan si cambian los datos

Sheet Comparador
B2: Comparador de series
B3: Elija hasta cuatro series en los desplegables, la frecuencia (mensual o anual) y si quiere verlas en Base 100 (cada serie dividida por su primer valor disponible). La tabla y el gráfico se recalculan con fórmulas sobre las hojas «Mensual» y «Anual».
P4: Serie | Q4: Columna en Mensual | R4: Columna en Anual
B5: Serie 1 | C5: Gasóleo C | D5: ← desplegables (deje en blanco las series que no quiera) | P5: OMIE | Q5: OMIE (€/kWh, sin imp.) | R5: OMIE (sin imp.)
B6: Serie 2 | C6: Pellet saco 15 kg | P6: MIBGAS | Q6: MIBGAS (€/kWh, sin imp.) | R6: MIBGAS (sin imp.)
B7: Serie 3 | P7: Gasóleo A | Q7: Gasóleo A (€/kWh, con imp.) | R7: Gasóleo A
B8: Serie 4 | P8: PVPC 2.0TD | Q8: PVPC 2.0TD (€/kWh, con imp.) | R8: PVPC 2.0TD
B9: Frecuencia | C9: Mensual | P9: TUR 2 | Q9: TUR 2 (€/kWh, con imp.) | R9: TUR 2
B10: Base 100 | C10: No | P10: Gasóleo C | Q10: Gasóleo C (€/kWh, con imp.) | R10: Gasóleo C
B11: Unidad: €/kWh (OMIE y MIBGAS sin impuestos; el resto con impuestos). Los huecos (#N/A) son periodos sin dato y no se dibujan. | P11: Butano | Q11: Butano (€/kWh, con imp.) | R11: Butano
G12: Columna en la hoja origen (auxiliar) | H12: =IF($C$5="",0,IF($C$9="Anual",IFERROR(MATCH(INDEX($R$5:$R$13,MATCH($C$5,$P$5:$P$13,0)),Anual!$B$1:$J$1,0),0),IFERROR(MATCH(INDEX($Q$5:$Q$13,MATCH($C$5,$P$5:$P$13,0)),Mensual!$B$1:$S$1,0),0))) | I12: =IF($C$6="",0,IF($C$9="Anual",IFERROR(MATCH(INDEX($R$5:$R$13,MATCH($C$6,$P$5:$P$13,0)),Anual!$B$1:$J$1,0),0),IFERROR(MATCH(INDEX($Q$5:$Q$13,MATCH($C$6,$P$5:$P$13,0)),Mensual!$B$1:$S$1,0),0))) | J12: =IF($C$7="",0,IF($C$9="Anual",IFERROR(MATCH(INDEX($R$5:$R$13,MATCH($C$7,$P$5:$P$13,0)),Anual!$B$1:$J$1,0),0),IFERROR(MATCH(INDEX($Q$5:$Q$13,MATCH($C$7,$P$5:$P$13,0)),Mensual!$B$1:$S$1,0),0))) | K12: =IF($C$8="",0,IF($C$9="Anual",IFERROR(MATCH(INDEX($R$5:$R$13,MATCH($C$8,$P$5:$P$13,0)),Anual!$B$1:$J$1,0),0),IFERROR(MATCH(INDEX($Q$5:$Q$13,MATCH($C$8,$P$5:$P$13,0)),Mensual!$B$1:$S$1,0),0))) | P12: Pellet saco 15 kg | Q12: Pellet saco 15 kg (€/kWh, con imp.) | R12: Pellet saco 15 kg
G13: Primer valor disponible (auxiliar, Base 100) | H13: =IFERROR(INDEX(H15:H96,MATCH(TRUE,INDEX(ISNUMBER(H15:H96),0),0)),NA()) | I13: =IFERROR(INDEX(I15:I96,MATCH(TRUE,INDEX(ISNUMBER(I15:I96),0),0)),NA()) | J13: =IFERROR(INDEX(J15:J96,MATCH(TRUE,INDEX(ISNUMBER(J15:J96),0),0)),NA()) | K13: =IFERROR(INDEX(K15:K96,MATCH(TRUE,INDEX(ISNUMBER(K15:K96),0),0)),NA()) | P13: Pellet granel | Q13: Pellet granel (€/kWh, con imp.) | R13: Pellet granel
A14: Periodo | B14: =IF($C$5="","(vacía)",$C$5) | C14: =IF($C$6="","(vacía)",$C$6) | D14: =IF($C$7="","(vacía)",$C$7) | E14: =IF($C$8="","(vacía)",$C$8) | H14: =IF($C$5="","(vacía)",$C$5&" (€/kWh)") | I14: =IF($C$6="","(vacía)",$C$6&" (€/kWh)") | J14: =IF($C$7="","(vacía)",$C$7&" (€/kWh)") | K14: =IF($C$8="","(vacía)",$C$8&" (€/kWh)")
A15: =IF($C$9="Anual",IF(1<=7,INDEX(Anual!$A$2:$A$8,1),""),IF(1<=82,INDEX(Mensual!$A$2:$A$83,1),"")) | B15: =IF($C$10="Sí",H15/H$13*100,H15) | C15: =IF($C$10="Sí",I15/I$13*100,I15) | D15: =IF($C$10="Sí",J15/J$13*100,J15) | E15: =IF($C$10="Sí",K15/K$13*100,K15) | H15: =IF(OR($A15="",H$12=0),NA(),IF($C$9="Anual",IF(INDEX(Anual!$B$2:$J$8,1,H$12)="",NA(),INDEX(Anual!$B$2:$J$8,1,H$12)),IF(INDEX(Mensual!$B$2:$S$83,1,H$12)="",NA(),INDEX(Mensual!$B$2:$S$83,1,H$12)))) | I15: =IF(OR($A15="",I$12=0),NA(),IF($C$9="Anual",IF(INDEX(Anual!$B$2:$J$8,1,I$12)="",NA(),INDEX(Anual!$B$2:$J$8,1,I$12)),IF(INDEX(Mensual!$B$2:$S$83,1,I$12)="",NA(),INDEX(Mensual!$B$2:$S$83,1,I$12)))) | J15: =IF(OR($A15="",J$12=0),NA(),IF($C$9="Anual",IF(INDEX(Anual!$B$2:$J$8,1,J$12)="",NA(),INDEX(Anual!$B$2:$J$8,1,J$12)),IF(INDEX(Mensual!$B$2:$S$83,1,J$12)="",NA(),INDEX(Mensual!$B$2:$S$83,1,J$12)))) | K15: =IF(OR($A15="",K$12=0),NA(),IF($C$9="Anual",IF(INDEX(Anual!$B$2:$J$8,1,K$12)="",NA(),INDEX(Anual!$B$2:$J$8,1,K$12)),IF(INDEX(Mensual!$B$2:$S$83,1,K$12)="",NA(),INDEX(Mensual!$B$2:$S$83,1,K$12))))
A16: =IF($C$9="Anual",IF(2<=7,INDEX(Anual!$A$2:$A$8,2),""),IF(2<=82,INDEX(Mensual!$A$2:$A$83,2),"")) | B16: =IF($C$10="Sí",H16/H$13*100,H16) | C16: =IF($C$10="Sí",I16/I$13*100,I16) | D16: =IF($C$10="Sí",J16/J$13*100,J16) | E16: =IF($C$10="Sí",K16/K$13*100,K16) | H16: =IF(OR($A16="",H$12=0),NA(),IF($C$9="Anual",IF(INDEX(Anual!$B$2:$J$8,2,H$12)="",NA(),INDEX(Anual!$B$2:$J$8,2,H$12)),IF(INDEX(Mensual!$B$2:$S$83,2,H$12)="",NA(),INDEX(Mensual!$B$2:$S$83,2,H$12)))) | I16: =IF(OR($A16="",I$12=0),NA(),IF($C$9="Anual",IF(INDEX(Anual!$B$2:$J$8,2,I$12)="",NA(),INDEX(Anual!$B$2:$J$8,2,I$12)),IF(INDEX(Mensual!$B$2:$S$83,2,I$12)="",NA(),INDEX(Mensual!$B$2:$S$83,2,I$12)))) | J16: =IF(OR($A16="",J$12=0),NA(),IF($C$9="Anual",IF(INDEX(Anual!$B$2:$J$8,2,J$12)="",NA(),INDEX(Anual!$B$2:$J$8,2,J$12)),IF(INDEX(Mensual!$B$2:$S$83,2,J$12)="",NA(),INDEX(Mensual!$B$2:$S$83,2,J$12)))) | K16: =IF(OR($A16="",K$12=0),NA(),IF($C$9="Anual",IF(INDEX(Anual!$B$2:$J$8,2,K$12)="",NA(),INDEX(Anual!$B$2:$J$8,2,K$12)),IF(INDEX(Mensual!$B$2:$S$83,2,K$12)="",NA(),INDEX(Mensual!$B$2:$S$83,2,K$12))))
A17: =IF($C$9="Anual",IF(3<=7,INDEX(Anual!$A$2:$A$8,3),""),IF(3<=82,INDEX(Mensual!$A$2:$A$83,3),"")) | B17: =IF($C$10="Sí",H17/H$13*100,H17) | C17: =IF($C$10="Sí",I17/I$13*100,I17) | D17: =IF($C$10="Sí",J17/J$13*100,J17) | E17: =IF($C$10="Sí",K17/K$13*100,K17) | H17: =IF(OR($A17="",H$12=0),NA(),IF($C$9="Anual",IF(INDEX(Anual!$B$2:$J$8,3,H$12)="",NA(),INDEX(Anual!$B$2:$J$8,3,H$12)),IF(INDEX(Mensual!$B$2:$S$83,3,H$12)="",NA(),INDEX(Mensual!$B$2:$S$83,3,H$12)))) | I17: =IF(OR($A17="",I$12=0),NA(),IF($C$9="Anual",IF(INDEX(Anual!$B$2:$J$8,3,I$12)="",NA(),INDEX(Anual!$B$2:$J$8,3,I$12)),IF(INDEX(Mensual!$B$2:$S$83,3,I$12)="",NA(),INDEX(Mensual!$B$2:$S$83,3,I$12)))) | J17: =IF(OR($A17="",J$12=0),NA(),IF($C$9="Anual",IF(INDEX(Anual!$B$2:$J$8,3,J$12)="",NA(),INDEX(Anual!$B$2:$J$8,3,J$12)),IF(INDEX(Mensual!$B$2:$S$83,3,J$12)="",NA(),INDEX(Mensual!$B$2:$S$83,3,J$12)))) | K17: =IF(OR($A17="",K$12=0),NA(),IF($C$9="Anual",IF(INDEX(Anual!$B$2:$J$8,3,K$12)="",NA(),INDEX(Anual!$B$2:$J$8,3,K$12)),IF(INDEX(Mensual!$B$2:$S$83,3,K$12)="",NA(),INDEX(Mensual!$B$2:$S$83,3,K$12))))
A18: =IF($C$9="Anual",IF(4<=7,INDEX(Anual!$A$2:$A$8,4),""),IF(4<=82,INDEX(Mensual!$A$2:$A$83,4),"")) | B18: =IF($C$10="Sí",H18/H$13*100,H18) | C18: =IF($C$10="Sí",I18/I$13*100,I18) | D18: =IF($C$10="Sí",J18/J$13*100,J18) | E18: =IF($C$10="Sí",K18/K$13*100,K18) | H18: =IF(OR($A18="",H$12=0),NA(),IF($C$9="Anual",IF(INDEX(Anual!$B$2:$J$8,4,H$12)="",NA(),INDEX(Anual!$B$2:$J$8,4,H$12)),IF(INDEX(Mensual!$B$2:$S$83,4,H$12)="",NA(),INDEX(Mensual!$B$2:$S$83,4,H$12)))) | I18: =IF(OR($A18="",I$12=0),NA(),IF($C$9="Anual",IF(INDEX(Anual!$B$2:$J$8,4,I$12)="",NA(),INDEX(Anual!$B$2:$J$8,4,I$12)),IF(INDEX(Mensual!$B$2:$S$83,4,I$12)="",NA(),INDEX(Mensual!$B$2:$S$83,4,I$12)))) | J18: =IF(OR($A18="",J$12=0),NA(),IF($C$9="Anual",IF(INDEX(Anual!$B$2:$J$8,4,J$12)="",NA(),INDEX(Anual!$B$2:$J$8,4,J$12)),IF(INDEX(Mensual!$B$2:$S$83,4,J$12)="",NA(),INDEX(Mensual!$B$2:$S$83,4,J$12)))) | K18: =IF(OR($A18="",K$12=0),NA(),IF($C$9="Anual",IF(INDEX(Anual!$B$2:$J$8,4,K$12)="",NA(),INDEX(Anual!$B$2:$J$8,4,K$12)),IF(INDEX(Mensual!$B$2:$S$83,4,K$12)="",NA(),INDEX(Mensual!$B$2:$S$83,4,K$12))))
A19: =IF($C$9="Anual",IF(5<=7,INDEX(Anual!$A$2:$A$8,5),""),IF(5<=82,INDEX(Mensual!$A$2:$A$83,5),"")) | B19: =IF($C$10="Sí",H19/H$13*100,H19) | C19: =IF($C$10="Sí",I19/I$13*100,I19) | D19: =IF($C$10="Sí",J19/J$13*100,J19) | E19: =IF($C$10="Sí",K19/K$13*100,K19) | H19: =IF(OR($A19="",H$12=0),NA(),IF($C$9="Anual",IF(INDEX(Anual!$B$2:$J$8,5,H$12)="",NA(),INDEX(Anual!$B$2:$J$8,5,H$12)),IF(INDEX(Mensual!$B$2:$S$83,5,H$12)="",NA(),INDEX(Mensual!$B$2:$S$83,5,H$12)))) | I19: =IF(OR($A19="",I$12=0),NA(),IF($C$9="Anual",IF(INDEX(Anual!$B$2:$J$8,5,I$12)="",NA(),INDEX(Anual!$B$2:$J$8,5,I$12)),IF(INDEX(Mensual!$B$2:$S$83,5,I$12)="",NA(),INDEX(Mensual!$B$2:$S$83,5,I$12)))) | J19: =IF(OR($A19="",J$12=0),NA(),IF($C$9="Anual",IF(INDEX(Anual!$B$2:$J$8,5,J$12)="",NA(),INDEX(Anual!$B$2:$J$8,5,J$12)),IF(INDEX(Mensual!$B$2:$S$83,5,J$12)="",NA(),INDEX(Mensual!$B$2:$S$83,5,J$12)))) | K19: =IF(OR($A19="",K$12=0),NA(),IF($C$9="Anual",IF(INDEX(Anual!$B$2:$J$8,5,K$12)="",NA(),INDEX(Anual!$B$2:$J$8,5,K$12)),IF(INDEX(Mensual!$B$2:$S$83,5,K$12)="",NA(),INDEX(Mensual!$B$2:$S$83,5,K$12))))
A20: =IF($C$9="Anual",IF(6<=7,INDEX(Anual!$A$2:$A$8,6),""),IF(6<=82,INDEX(Mensual!$A$2:$A$83,6),"")) | B20: =IF($C$10="Sí",H20/H$13*100,H20) | C20: =IF($C$10="Sí",I20/I$13*100,I20) | D20: =IF($C$10="Sí",J20/J$13*100,J20) | E20: =IF($C$10="Sí",K20/K$13*100,K20) | H20: =IF(OR($A20="",H$12=0),NA(),IF($C$9="Anual",IF(INDEX(Anual!$B$2:$J$8,6,H$12)="",NA(),INDEX(Anual!$B$2:$J$8,6,H$12)),IF(INDEX(Mensual!$B$2:$S$83,6,H$12)="",NA(),INDEX(Mensual!$B$2:$S$83,6,H$12)))) | I20: =IF(OR($A20="",I$12=0),NA(),IF($C$9="Anual",IF(INDEX(Anual!$B$2:$J$8,6,I$12)="",NA(),INDEX(Anual!$B$2:$J$8,6,I$12)),IF(INDEX(Mensual!$B$2:$S$83,6,I$12)="",NA(),INDEX(Mensual!$B$2:$S$83,6,I$12)))) | J20: =IF(OR($A20="",J$12=0),NA(),IF($C$9="Anual",IF(INDEX(Anual!$B$2:$J$8,6,J$12)="",NA(),INDEX(Anual!$B$2:$J$8,6,J$12)),IF(INDEX(Mensual!$B$2:$S$83,6,J$12)="",NA(),INDEX(Mensual!$B$2:$S$83,6,J$12)))) | K20: =IF(OR($A20="",K$12=0),NA(),IF($C$9="Anual",IF(INDEX(Anual!$B$2:$J$8,6,K$12)="",NA(),INDEX(Anual!$B$2:$J$8,6,K$12)),IF(INDEX(Mensual!$B$2:$S$83,6,K$12)="",NA(),INDEX(Mensual!$B$2:$S$83,6,K$12))))
A21: =IF($C$9="Anual",IF(7<=7,INDEX(Anual!$A$2:$A$8,7),""),IF(7<=82,INDEX(Mensual!$A$2:$A$83,7),"")) | B21: =IF($C$10="Sí",H21/H$13*100,H21) | C21: =IF($C$10="Sí",I21/I$13*100,I21) | D21: =IF($C$10="Sí",J21/J$13*100,J21) | E21: =IF($C$10="Sí",K21/K$13*100,K21) | H21: =IF(OR($A21="",H$12=0),NA(),IF($C$9="Anual",IF(INDEX(Anual!$B$2:$J$8,7,H$12)="",NA(),INDEX(Anual!$B$2:$J$8,7,H$12)),IF(INDEX(Mensual!$B$2:$S$83,7,H$12)="",NA(),INDEX(Mensual!$B$2:$S$83,7,H$12)))) | I21: =IF(OR($A21="",I$12=0),NA(),IF($C$9="Anual",IF(INDEX(Anual!$B$2:$J$8,7,I$12)="",NA(),INDEX(Anual!$B$2:$J$8,7,I$12)),IF(INDEX(Mensual!$B$2:$S$83,7,I$12)="",NA(),INDEX(Mensual!$B$2:$S$83,7,I$12)))) | J21: =IF(OR($A21="",J$12=0),NA(),IF($C$9="Anual",IF(INDEX(Anual!$B$2:$J$8,7,J$12)="",NA(),INDEX(Anual!$B$2:$J$8,7,J$12)),IF(INDEX(Mensual!$B$2:$S$83,7,J$12)="",NA(),INDEX(Mensual!$B$2:$S$83,7,J$12)))) | K21: =IF(OR($A21="",K$12=0),NA(),IF($C$9="Anual",IF(INDEX(Anual!$B$2:$J$8,7,K$12)="",NA(),INDEX(Anual!$B$2:$J$8,7,K$12)),IF(INDEX(Mensual!$B$2:$S$83,7,K$12)="",NA(),INDEX(Mensual!$B$2:$S$83,7,K$12))))
A22: =IF($C$9="Anual",IF(8<=7,INDEX(Anual!$A$2:$A$8,8),""),IF(8<=82,INDEX(Mensual!$A$2:$A$83,8),"")) | B22: =IF($C$10="Sí",H22/H$13*100,H22) | C22: =IF($C$10="Sí",I22/I$13*100,I22) | D22: =IF($C$10="Sí",J22/J$13*100,J22) | E22: =IF($C$10="Sí",K22/K$13*100,K22) | H22: =IF(OR($A22="",H$12=0),NA(),IF($C$9="Anual",IF(INDEX(Anual!$B$2:$J$8,8,H$12)="",NA(),INDEX(Anual!$B$2:$J$8,8,H$12)),IF(INDEX(Mensual!$B$2:$S$83,8,H$12)="",NA(),INDEX(Mensual!$B$2:$S$83,8,H$12)))) | I22: =IF(OR($A22="",I$12=0),NA(),IF($C$9="Anual",IF(INDEX(Anual!$B$2:$J$8,8,I$12)="",NA(),INDEX(Anual!$B$2:$J$8,8,I$12)),IF(INDEX(Mensual!$B$2:$S$83,8,I$12)="",NA(),INDEX(Mensual!$B$2:$S$83,8,I$12)))) | J22: =IF(OR($A22="",J$12=0),NA(),IF($C$9="Anual",IF(INDEX(Anual!$B$2:$J$8,8,J$12)="",NA(),INDEX(Anual!$B$2:$J$8,8,J$12)),IF(INDEX(Mensual!$B$2:$S$83,8,J$12)="",NA(),INDEX(Mensual!$B$2:$S$83,8,J$12)))) | K22: =IF(OR($A22="",K$12=0),NA(),IF($C$9="Anual",IF(INDEX(Anual!$B$2:$J$8,8,K$12)="",NA(),INDEX(Anual!$B$2:$J$8,8,K$12)),IF(INDEX(Mensual!$B$2:$S$83,8,K$12)="",NA(),INDEX(Mensual!$B$2:$S$83,8,K$12))))
A23: =IF($C$9="Anual",IF(9<=7,INDEX(Anual!$A$2:$A$8,9),""),IF(9<=82,INDEX(Mensual!$A$2:$A$83,9),"")) | B23: =IF($C$10="Sí",H23/H$13*100,H23) | C23: =IF($C$10="Sí",I23/I$13*100,I23) | D23: =IF($C$10="Sí",J23/J$13*100,J23) | E23: =IF($C$10="Sí",K23/K$13*100,K23) | H23: =IF(OR($A23="",H$12=0),NA(),IF($C$9="Anual",IF(INDEX(Anual!$B$2:$J$8,9,H$12)="",NA(),INDEX(Anual!$B$2:$J$8,9,H$12)),IF(INDEX(Mensual!$B$2:$S$83,9,H$12)="",NA(),INDEX(Mensual!$B$2:$S$83,9,H$12)))) | I23: =IF(OR($A23="",I$12=0),NA(),IF($C$9="Anual",IF(INDEX(Anual!$B$2:$J$8,9,I$12)="",NA(),INDEX(Anual!$B$2:$J$8,9,I$12)),IF(INDEX(Mensual!$B$2:$S$83,9,I$12)="",NA(),INDEX(Mensual!$B$2:$S$83,9,I$12)))) | J23: =IF(OR($A23="",J$12=0),NA(),IF($C$9="Anual",IF(INDEX(Anual!$B$2:$J$8,9,J$12)="",NA(),INDEX(Anual!$B$2:$J$8,9,J$12)),IF(INDEX(Mensual!$B$2:$S$83,9,J$12)="",NA(),INDEX(Mensual!$B$2:$S$83,9,J$12)))) | K23: =IF(OR($A23="",K$12=0),NA(),IF($C$9="Anual",IF(INDEX(Anual!$B$2:$J$8,9,K$12)="",NA(),INDEX(Anual!$B$2:$J$8,9,K$12)),IF(INDEX(Mensual!$B$2:$S$83,9,K$12)="",NA(),INDEX(Mensual!$B$2:$S$83,9,K$12))))
A24: =IF($C$9="Anual",IF(10<=7,INDEX(Anual!$A$2:$A$8,10),""),IF(10<=82,INDEX(Mensual!$A$2:$A$83,10),"")) | B24: =IF($C$10="Sí",H24/H$13*100,H24) | C24: =IF($C$10="Sí",I24/I$13*100,I24) | D24: =IF($C$10="Sí",J24/J$13*100,J24) | E24: =IF($C$10="Sí",K24/K$13*100,K24) | H24: =IF(OR($A24="",H$12=0),NA(),IF($C$9="Anual",IF(INDEX(Anual!$B$2:$J$8,10,H$12)="",NA(),INDEX(Anual!$B$2:$J$8,10,H$12)),IF(INDEX(Mensual!$B$2:$S$83,10,H$12)="",NA(),INDEX(Mensual!$B$2:$S$83,10,H$12)))) | I24: =IF(OR($A24="",I$12=0),NA(),IF($C$9="Anual",IF(INDEX(Anual!$B$2:$J$8,10,I$12)="",NA(),INDEX(Anual!$B$2:$J$8,10,I$12)),IF(INDEX(Mensual!$B$2:$S$83,10,I$12)="",NA(),INDEX(Mensual!$B$2:$S$83,10,I$12)))) | J24: =IF(OR($A24="",J$12=0),NA(),IF($C$9="Anual",IF(INDEX(Anual!$B$2:$J$8,10,J$12)="",NA(),INDEX(Anual!$B$2:$J$8,10,J$12)),IF(INDEX(Mensual!$B$2:$S$83,10,J$12)="",NA(),INDEX(Mensual!$B$2:$S$83,10,J$12)))) | K24: =IF(OR($A24="",K$12=0),NA(),IF($C$9="Anual",IF(INDEX(Anual!$B$2:$J$8,10,K$12)="",NA(),INDEX(Anual!$B$2:$J$8,10,K$12)),IF(INDEX(Mensual!$B$2:$S$83,10,K$12)="",NA(),INDEX(Mensual!$B$2:$S$83,10,K$12))))
A25: =IF($C$9="Anual",IF(11<=7,INDEX(Anual!$A$2:$A$8,11),""),IF(11<=82,INDEX(Mensual!$A$2:$A$83,11),"")) | B25: =IF($C$10="Sí",H25/H$13*100,H25) | C25: =IF($C$10="Sí",I25/I$13*100,I25) | D25: =IF($C$10="Sí",J25/J$13*100,J25) | E25: =IF($C$10="Sí",K25/K$13*100,K25) | H25: =IF(OR($A25="",H$12=0),NA(),IF($C$9="Anual",IF(INDEX(Anual!$B$2:$J$8,11,H$12)="",NA(),INDEX(Anual!$B$2:$J$8,11,H$12)),IF(INDEX(Mensual!$B$2:$S$83,11,H$12)="",NA(),INDEX(Mensual!$B$2:$S$83,11,H$12)))) | I25: =IF(OR($A25="",I$12=0),NA(),IF($C$9="Anual",IF(INDEX(Anual!$B$2:$J$8,11,I$12)="",NA(),INDEX(Anual!$B$2:$J$8,11,I$12)),IF(INDEX(Mensual!$B$2:$S$83,11,I$12)="",NA(),INDEX(Mensual!$B$2:$S$83,11,I$12)))) | J25: =IF(OR($A25="",J$12=0),NA(),IF($C$9="Anual",IF(INDEX(Anual!$B$2:$J$8,11,J$12)="",NA(),INDEX(Anual!$B$2:$J$8,11,J$12)),IF(INDEX(Mensual!$B$2:$S$83,11,J$12)="",NA(),INDEX(Mensual!$B$2:$S$83,11,J$12)))) | K25: =IF(OR($A25="",K$12=0),NA(),IF($C$9="Anual",IF(INDEX(Anual!$B$2:$J$8,11,K$12)="",NA(),INDEX(Anual!$B$2:$J$8,11,K$12)),IF(INDEX(Mensual!$B$2:$S$83,11,K$12)="",NA(),INDEX(Mensual!$B$2:$S$83,11,K$12))))
A26: =IF($C$9="Anual",IF(12<=7,INDEX(Anual!$A$2:$A$8,12),""),IF(12<=82,INDEX(Mensual!$A$2:$A$83,12),"")) | B26: =IF($C$10="Sí",H26/H$13*100,H26) | C26: =IF($C$10="Sí",I26/I$13*100,I26) | D26: =IF($C$10="Sí",J26/J$13*100,J26) | E26: =IF($C$10="Sí",K26/K$13*100,K26) | H26: =IF(OR($A26="",H$12=0),NA(),IF($C$9="Anual",IF(INDEX(Anual!$B$2:$J$8,12,H$12)="",NA(),INDEX(Anual!$B$2:$J$8,12,H$12)),IF(INDEX(Mensual!$B$2:$S$83,12,H$12)="",NA(),INDEX(Mensual!$B$2:$S$83,12,H$12)))) | I26: =IF(OR($A26="",I$12=0),NA(),IF($C$9="Anual",IF(INDEX(Anual!$B$2:$J$8,12,I$12)="",NA(),INDEX(Anual!$B$2:$J$8,12,I$12)),IF(INDEX(Mensual!$B$2:$S$83,12,I$12)="",NA(),INDEX(Mensual!$B$2:$S$83,12,I$12)))) | J26: =IF(OR($A26="",J$12=0),NA(),IF($C$9="Anual",IF(INDEX(Anual!$B$2:$J$8,12,J$12)="",NA(),INDEX(Anual!$B$2:$J$8,12,J$12)),IF(INDEX(Mensual!$B$2:$S$83,12,J$12)="",NA(),INDEX(Mensual!$B$2:$S$83,12,J$12)))) | K26: =IF(OR($A26="",K$12=0),NA(),IF($C$9="Anual",IF(INDEX(Anual!$B$2:$J$8,12,K$12)="",NA(),INDEX(Anual!$B$2:$J$8,12,K$12)),IF(INDEX(Mensual!$B$2:$S$83,12,K$12)="",NA(),INDEX(Mensual!$B$2:$S$83,12,K$12))))
A27: =IF($C$9="Anual",IF(13<=7,INDEX(Anual!$A$2:$A$8,13),""),IF(13<=82,INDEX(Mensual!$A$2:$A$83,13),"")) | B27: =IF($C$10="Sí",H27/H$13*100,H27) | C27: =IF($C$10="Sí",I27/I$13*100,I27) | D27: =IF($C$10="Sí",J27/J$13*100,J27) | E27: =IF($C$10="Sí",K27/K$13*100,K27) | H27: =IF(OR($A27="",H$12=0),NA(),IF($C$9="Anual",IF(INDEX(Anual!$B$2:$J$8,13,H$12)="",NA(),INDEX(Anual!$B$2:$J$8,13,H$12)),IF(INDEX(Mensual!$B$2:$S$83,13,H$12)="",NA(),INDEX(Mensual!$B$2:$S$83,13,H$12)))) | I27: =IF(OR($A27="",I$12=0),NA(),IF($C$9="Anual",IF(INDEX(Anual!$B$2:$J$8,13,I$12)="",NA(),INDEX(Anual!$B$2:$J$8,13,I$12)),IF(INDEX(Mensual!$B$2:$S$83,13,I$12)="",NA(),INDEX(Mensual!$B$2:$S$83,13,I$12)))) | J27: =IF(OR($A27="",J$12=0),NA(),IF($C$9="Anual",IF(INDEX(Anual!$B$2:$J$8,13,J$12)="",NA(),INDEX(Anual!$B$2:$J$8,13,J$12)),IF(INDEX(Mensual!$B$2:$S$83,13,J$12)="",NA(),INDEX(Mensual!$B$2:$S$83,13,J$12)))) | K27: =IF(OR($A27="",K$12=0),NA(),IF($C$9="Anual",IF(INDEX(Anual!$B$2:$J$8,13,K$12)="",NA(),INDEX(Anual!$B$2:$J$8,13,K$12)),IF(INDEX(Mensual!$B$2:$S$83,13,K$12)="",NA(),INDEX(Mensual!$B$2:$S$83,13,K$12))))
A28: =IF($C$9="Anual",IF(14<=7,INDEX(Anual!$A$2:$A$8,14),""),IF(14<=82,INDEX(Mensual!$A$2:$A$83,14),"")) | B28: =IF($C$10="Sí",H28/H$13*100,H28) | C28: =IF($C$10="Sí",I28/I$13*100,I28) | D28: =IF($C$10="Sí",J28/J$13*100,J28) | E28: =IF($C$10="Sí",K28/K$13*100,K28) | H28: =IF(OR($A28="",H$12=0),NA(),IF($C$9="Anual",IF(INDEX(Anual!$B$2:$J$8,14,H$12)="",NA(),INDEX(Anual!$B$2:$J$8,14,H$12)),IF(INDEX(Mensual!$B$2:$S$83,14,H$12)="",NA(),INDEX(Mensual!$B$2:$S$83,14,H$12)))) | I28: =IF(OR($A28="",I$12=0),NA(),IF($C$9="Anual",IF(INDEX(Anual!$B$2:$J$8,14,I$12)="",NA(),INDEX(Anual!$B$2:$J$8,14,I$12)),IF(INDEX(Mensual!$B$2:$S$83,14,I$12)="",NA(),INDEX(Mensual!$B$2:$S$83,14,I$12)))) | J28: =IF(OR($A28="",J$12=0),NA(),IF($C$9="Anual",IF(INDEX(Anual!$B$2:$J$8,14,J$12)="",NA(),INDEX(Anual!$B$2:$J$8,14,J$12)),IF(INDEX(Mensual!$B$2:$S$83,14,J$12)="",NA(),INDEX(Mensual!$B$2:$S$83,14,J$12)))) | K28: =IF(OR($A28="",K$12=0),NA(),IF($C$9="Anual",IF(INDEX(Anual!$B$2:$J$8,14,K$12)="",NA(),INDEX(Anual!$B$2:$J$8,14,K$12)),IF(INDEX(Mensual!$B$2:$S$83,14,K$12)="",NA(),INDEX(Mensual!$B$2:$S$83,14,K$12))))
A29: =IF($C$9="Anual",IF(15<=7,INDEX(Anual!$A$2:$A$8,15),""),IF(15<=82,INDEX(Mensual!$A$2:$A$83,15),"")) | B29: =IF($C$10="Sí",H29/H$13*100,H29) | C29: =IF($C$10="Sí",I29/I$13*100,I29) | D29: =IF($C$10="Sí",J29/J$13*100,J29) | E29: =IF($C$10="Sí",K29/K$13*100,K29) | H29: =IF(OR($A29="",H$12=0),NA(),IF($C$9="Anual",IF(INDEX(Anual!$B$2:$J$8,15,H$12)="",NA(),INDEX(Anual!$B$2:$J$8,15,H$12)),IF(INDEX(Mensual!$B$2:$S$83,15,H$12)="",NA(),INDEX(Mensual!$B$2:$S$83,15,H$12)))) | I29: =IF(OR($A29="",I$12=0),NA(),IF($C$9="Anual",IF(INDEX(Anual!$B$2:$J$8,15,I$12)="",NA(),INDEX(Anual!$B$2:$J$8,15,I$12)),IF(INDEX(Mensual!$B$2:$S$83,15,I$12)="",NA(),INDEX(Mensual!$B$2:$S$83,15,I$12)))) | J29: =IF(OR($A29="",J$12=0),NA(),IF($C$9="Anual",IF(INDEX(Anual!$B$2:$J$8,15,J$12)="",NA(),INDEX(Anual!$B$2:$J$8,15,J$12)),IF(INDEX(Mensual!$B$2:$S$83,15,J$12)="",NA(),INDEX(Mensual!$B$2:$S$83,15,J$12)))) | K29: =IF(OR($A29="",K$12=0),NA(),IF($C$9="Anual",IF(INDEX(Anual!$B$2:$J$8,15,K$12)="",NA(),INDEX(Anual!$B$2:$J$8,15,K$12)),IF(INDEX(Mensual!$B$2:$S$83,15,K$12)="",NA(),INDEX(Mensual!$B$2:$S$83,15,K$12))))
A30: =IF($C$9="Anual",IF(16<=7,INDEX(Anual!$A$2:$A$8,16),""),IF(16<=82,INDEX(Mensual!$A$2:$A$83,16),"")) | B30: =IF($C$10="Sí",H30/H$13*100,H30) | C30: =IF($C$10="Sí",I30/I$13*100,I30) | D30: =IF($C$10="Sí",J30/J$13*100,J30) | E30: =IF($C$10="Sí",K30/K$13*100,K30) | H30: =IF(OR($A30="",H$12=0),NA(),IF($C$9="Anual",IF(INDEX(Anual!$B$2:$J$8,16,H$12)="",NA(),INDEX(Anual!$B$2:$J$8,16,H$12)),IF(INDEX(Mensual!$B$2:$S$83,16,H$12)="",NA(),INDEX(Mensual!$B$2:$S$83,16,H$12)))) | I30: =IF(OR($A30="",I$12=0),NA(),IF($C$9="Anual",IF(INDEX(Anual!$B$2:$J$8,16,I$12)="",NA(),INDEX(Anual!$B$2:$J$8,16,I$12)),IF(INDEX(Mensual!$B$2:$S$83,16,I$12)="",NA(),INDEX(Mensual!$B$2:$S$83,16,I$12)))) | J30: =IF(OR($A30="",J$12=0),NA(),IF($C$9="Anual",IF(INDEX(Anual!$B$2:$J$8,16,J$12)="",NA(),INDEX(Anual!$B$2:$J$8,16,J$12)),IF(INDEX(Mensual!$B$2:$S$83,16,J$12)="",NA(),INDEX(Mensual!$B$2:$S$83,16,J$12)))) | K30: =IF(OR($A30="",K$12=0),NA(),IF($C$9="Anual",IF(INDEX(Anual!$B$2:$J$8,16,K$12)="",NA(),INDEX(Anual!$B$2:$J$8,16,K$12)),IF(INDEX(Mensual!$B$2:$S$83,16,K$12)="",NA(),INDEX(Mensual!$B$2:$S$83,16,K$12))))
A31: =IF($C$9="Anual",IF(17<=7,INDEX(Anual!$A$2:$A$8,17),""),IF(17<=82,INDEX(Mensual!$A$2:$A$83,17),"")) | B31: =IF($C$10="Sí",H31/H$13*100,H31) | C31: =IF($C$10="Sí",I31/I$13*100,I31) | D31: =IF($C$10="Sí",J31/J$13*100,J31) | E31: =IF($C$10="Sí",K31/K$13*100,K31) | H31: =IF(OR($A31="",H$12=0),NA(),IF($C$9="Anual",IF(INDEX(Anual!$B$2:$J$8,17,H$12)="",NA(),INDEX(Anual!$B$2:$J$8,17,H$12)),IF(INDEX(Mensual!$B$2:$S$83,17,H$12)="",NA(),INDEX(Mensual!$B$2:$S$83,17,H$12)))) | I31: =IF(OR($A31="",I$12=0),NA(),IF($C$9="Anual",IF(INDEX(Anual!$B$2:$J$8,17,I$12)="",NA(),INDEX(Anual!$B$2:$J$8,17,I$12)),IF(INDEX(Mensual!$B$2:$S$83,17,I$12)="",NA(),INDEX(Mensual!$B$2:$S$83,17,I$12)))) | J31: =IF(OR($A31="",J$12=0),NA(),IF($C$9="Anual",IF(INDEX(Anual!$B$2:$J$8,17,J$12)="",NA(),INDEX(Anual!$B$2:$J$8,17,J$12)),IF(INDEX(Mensual!$B$2:$S$83,17,J$12)="",NA(),INDEX(Mensual!$B$2:$S$83,17,J$12)))) | K31: =IF(OR($A31="",K$12=0),NA(),IF($C$9="Anual",IF(INDEX(Anual!$B$2:$J$8,17,K$12)="",NA(),INDEX(Anual!$B$2:$J$8,17,K$12)),IF(INDEX(Mensual!$B$2:$S$83,17,K$12)="",NA(),INDEX(Mensual!$B$2:$S$83,17,K$12))))
A32: =IF($C$9="Anual",IF(18<=7,INDEX(Anual!$A$2:$A$8,18),""),IF(18<=82,INDEX(Mensual!$A$2:$A$83,18),"")) | B32: =IF($C$10="Sí",H32/H$13*100,H32) | C32: =IF($C$10="Sí",I32/I$13*100,I32) | D32: =IF($C$10="Sí",J32/J$13*100,J32) | E32: =IF($C$10="Sí",K32/K$13*100,K32) | H32: =IF(OR($A32="",H$12=0),NA(),IF($C$9="Anual",IF(INDEX(Anual!$B$2:$J$8,18,H$12)="",NA(),INDEX(Anual!$B$2:$J$8,18,H$12)),IF(INDEX(Mensual!$B$2:$S$83,18,H$12)="",NA(),INDEX(Mensual!$B$2:$S$83,18,H$12)))) | I32: =IF(OR($A32="",I$12=0),NA(),IF($C$9="Anual",IF(INDEX(Anual!$B$2:$J$8,18,I$12)="",NA(),INDEX(Anual!$B$2:$J$8,18,I$12)),IF(INDEX(Mensual!$B$2:$S$83,18,I$12)="",NA(),INDEX(Mensual!$B$2:$S$83,18,I$12)))) | J32: =IF(OR($A32="",J$12=0),NA(),IF($C$9="Anual",IF(INDEX(Anual!$B$2:$J$8,18,J$12)="",NA(),INDEX(Anual!$B$2:$J$8,18,J$12)),IF(INDEX(Mensual!$B$2:$S$83,18,J$12)="",NA(),INDEX(Mensual!$B$2:$S$83,18,J$12)))) | K32: =IF(OR($A32="",K$12=0),NA(),IF($C$9="Anual",IF(INDEX(Anual!$B$2:$J$8,18,K$12)="",NA(),INDEX(Anual!$B$2:$J$8,18,K$12)),IF(INDEX(Mensual!$B$2:$S$83,18,K$12)="",NA(),INDEX(Mensual!$B$2:$S$83,18,K$12))))
A33: =IF($C$9="Anual",IF(19<=7,INDEX(Anual!$A$2:$A$8,19),""),IF(19<=82,INDEX(Mensual!$A$2:$A$83,19),"")) | B33: =IF($C$10="Sí",H33/H$13*100,H33) | C33: =IF($C$10="Sí",I33/I$13*100,I33) | D33: =IF($C$10="Sí",J33/J$13*100,J33) | E33: =IF($C$10="Sí",K33/K$13*100,K33) | H33: =IF(OR($A33="",H$12=0),NA(),IF($C$9="Anual",IF(INDEX(Anual!$B$2:$J$8,19,H$12)="",NA(),INDEX(Anual!$B$2:$J$8,19,H$12)),IF(INDEX(Mensual!$B$2:$S$83,19,H$12)="",NA(),INDEX(Mensual!$B$2:$S$83,19,H$12)))) | I33: =IF(OR($A33="",I$12=0),NA(),IF($C$9="Anual",IF(INDEX(Anual!$B$2:$J$8,19,I$12)="",NA(),INDEX(Anual!$B$2:$J$8,19,I$12)),IF(INDEX(Mensual!$B$2:$S$83,19,I$12)="",NA(),INDEX(Mensual!$B$2:$S$83,19,I$12)))) | J33: =IF(OR($A33="",J$12=0),NA(),IF($C$9="Anual",IF(INDEX(Anual!$B$2:$J$8,19,J$12)="",NA(),INDEX(Anual!$B$2:$J$8,19,J$12)),IF(INDEX(Mensual!$B$2:$S$83,19,J$12)="",NA(),INDEX(Mensual!$B$2:$S$83,19,J$12)))) | K33: =IF(OR($A33="",K$12=0),NA(),IF($C$9="Anual",IF(INDEX(Anual!$B$2:$J$8,19,K$12)="",NA(),INDEX(Anual!$B$2:$J$8,19,K$12)),IF(INDEX(Mensual!$B$2:$S$83,19,K$12)="",NA(),INDEX(Mensual!$B$2:$S$83,19,K$12))))
A34: =IF($C$9="Anual",IF(20<=7,INDEX(Anual!$A$2:$A$8,20),""),IF(20<=82,INDEX(Mensual!$A$2:$A$83,20),"")) | B34: =IF($C$10="Sí",H34/H$13*100,H34) | C34: =IF($C$10="Sí",I34/I$13*100,I34) | D34: =IF($C$10="Sí",J34/J$13*100,J34) | E34: =IF($C$10="Sí",K34/K$13*100,K34) | H34: =IF(OR($A34="",H$12=0),NA(),IF($C$9="Anual",IF(INDEX(Anual!$B$2:$J$8,20,H$12)="",NA(),INDEX(Anual!$B$2:$J$8,20,H$12)),IF(INDEX(Mensual!$B$2:$S$83,20,H$12)="",NA(),INDEX(Mensual!$B$2:$S$83,20,H$12)))) | I34: =IF(OR($A34="",I$12=0),NA(),IF($C$9="Anual",IF(INDEX(Anual!$B$2:$J$8,20,I$12)="",NA(),INDEX(Anual!$B$2:$J$8,20,I$12)),IF(INDEX(Mensual!$B$2:$S$83,20,I$12)="",NA(),INDEX(Mensual!$B$2:$S$83,20,I$12)))) | J34: =IF(OR($A34="",J$12=0),NA(),IF($C$9="Anual",IF(INDEX(Anual!$B$2:$J$8,20,J$12)="",NA(),INDEX(Anual!$B$2:$J$8,20,J$12)),IF(INDEX(Mensual!$B$2:$S$83,20,J$12)="",NA(),INDEX(Mensual!$B$2:$S$83,20,J$12)))) | K34: =IF(OR($A34="",K$12=0),NA(),IF($C$9="Anual",IF(INDEX(Anual!$B$2:$J$8,20,K$12)="",NA(),INDEX(Anual!$B$2:$J$8,20,K$12)),IF(INDEX(Mensual!$B$2:$S$83,20,K$12)="",NA(),INDEX(Mensual!$B$2:$S$83,20,K$12))))
A35: =IF($C$9="Anual",IF(21<=7,INDEX(Anual!$A$2:$A$8,21),""),IF(21<=82,INDEX(Mensual!$A$2:$A$83,21),"")) | B35: =IF($C$10="Sí",H35/H$13*100,H35) | C35: =IF($C$10="Sí",I35/I$13*100,I35) | D35: =IF($C$10="Sí",J35/J$13*100,J35) | E35: =IF($C$10="Sí",K35/K$13*100,K35) | H35: =IF(OR($A35="",H$12=0),NA(),IF($C$9="Anual",IF(INDEX(Anual!$B$2:$J$8,21,H$12)="",NA(),INDEX(Anual!$B$2:$J$8,21,H$12)),IF(INDEX(Mensual!$B$2:$S$83,21,H$12)="",NA(),INDEX(Mensual!$B$2:$S$83,21,H$12)))) | I35: =IF(OR($A35="",I$12=0),NA(),IF($C$9="Anual",IF(INDEX(Anual!$B$2:$J$8,21,I$12)="",NA(),INDEX(Anual!$B$2:$J$8,21,I$12)),IF(INDEX(Mensual!$B$2:$S$83,21,I$12)="",NA(),INDEX(Mensual!$B$2:$S$83,21,I$12)))) | J35: =IF(OR($A35="",J$12=0),NA(),IF($C$9="Anual",IF(INDEX(Anual!$B$2:$J$8,21,J$12)="",NA(),INDEX(Anual!$B$2:$J$8,21,J$12)),IF(INDEX(Mensual!$B$2:$S$83,21,J$12)="",NA(),INDEX(Mensual!$B$2:$S$83,21,J$12)))) | K35: =IF(OR($A35="",K$12=0),NA(),IF($C$9="Anual",IF(INDEX(Anual!$B$2:$J$8,21,K$12)="",NA(),INDEX(Anual!$B$2:$J$8,21,K$12)),IF(INDEX(Mensual!$B$2:$S$83,21,K$12)="",NA(),INDEX(Mensual!$B$2:$S$83,21,K$12))))
A36: =IF($C$9="Anual",IF(22<=7,INDEX(Anual!$A$2:$A$8,22),""),IF(22<=82,INDEX(Mensual!$A$2:$A$83,22),"")) | B36: =IF($C$10="Sí",H36/H$13*100,H36) | C36: =IF($C$10="Sí",I36/I$13*100,I36) | D36: =IF($C$10="Sí",J36/J$13*100,J36) | E36: =IF($C$10="Sí",K36/K$13*100,K36) | H36: =IF(OR($A36="",H$12=0),NA(),IF($C$9="Anual",IF(INDEX(Anual!$B$2:$J$8,22,H$12)="",NA(),INDEX(Anual!$B$2:$J$8,22,H$12)),IF(INDEX(Mensual!$B$2:$S$83,22,H$12)="",NA(),INDEX(Mensual!$B$2:$S$83,22,H$12)))) | I36: =IF(OR($A36="",I$12=0),NA(),IF($C$9="Anual",IF(INDEX(Anual!$B$2:$J$8,22,I$12)="",NA(),INDEX(Anual!$B$2:$J$8,22,I$12)),IF(INDEX(Mensual!$B$2:$S$83,22,I$12)="",NA(),INDEX(Mensual!$B$2:$S$83,22,I$12)))) | J36: =IF(OR($A36="",J$12=0),NA(),IF($C$9="Anual",IF(INDEX(Anual!$B$2:$J$8,22,J$12)="",NA(),INDEX(Anual!$B$2:$J$8,22,J$12)),IF(INDEX(Mensual!$B$2:$S$83,22,J$12)="",NA(),INDEX(Mensual!$B$2:$S$83,22,J$12)))) | K36: =IF(OR($A36="",K$12=0),NA(),IF($C$9="Anual",IF(INDEX(Anual!$B$2:$J$8,22,K$12)="",NA(),INDEX(Anual!$B$2:$J$8,22,K$12)),IF(INDEX(Mensual!$B$2:$S$83,22,K$12)="",NA(),INDEX(Mensual!$B$2:$S$83,22,K$12))))
A37: =IF($C$9="Anual",IF(23<=7,INDEX(Anual!$A$2:$A$8,23),""),IF(23<=82,INDEX(Mensual!$A$2:$A$83,23),"")) | B37: =IF($C$10="Sí",H37/H$13*100,H37) | C37: =IF($C$10="Sí",I37/I$13*100,I37) | D37: =IF($C$10="Sí",J37/J$13*100,J37) | E37: =IF($C$10="Sí",K37/K$13*100,K37) | H37: =IF(OR($A37="",H$12=0),NA(),IF($C$9="Anual",IF(INDEX(Anual!$B$2:$J$8,23,H$12)="",NA(),INDEX(Anual!$B$2:$J$8,23,H$12)),IF(INDEX(Mensual!$B$2:$S$83,23,H$12)="",NA(),INDEX(Mensual!$B$2:$S$83,23,H$12)))) | I37: =IF(OR($A37="",I$12=0),NA(),IF($C$9="Anual",IF(INDEX(Anual!$B$2:$J$8,23,I$12)="",NA(),INDEX(Anual!$B$2:$J$8,23,I$12)),IF(INDEX(Mensual!$B$2:$S$83,23,I$12)="",NA(),INDEX(Mensual!$B$2:$S$83,23,I$12)))) | J37: =IF(OR($A37="",J$12=0),NA(),IF($C$9="Anual",IF(INDEX(Anual!$B$2:$J$8,23,J$12)="",NA(),INDEX(Anual!$B$2:$J$8,23,J$12)),IF(INDEX(Mensual!$B$2:$S$83,23,J$12)="",NA(),INDEX(Mensual!$B$2:$S$83,23,J$12)))) | K37: =IF(OR($A37="",K$12=0),NA(),IF($C$9="Anual",IF(INDEX(Anual!$B$2:$J$8,23,K$12)="",NA(),INDEX(Anual!$B$2:$J$8,23,K$12)),IF(INDEX(Mensual!$B$2:$S$83,23,K$12)="",NA(),INDEX(Mensual!$B$2:$S$83,23,K$12))))
A38: =IF($C$9="Anual",IF(24<=7,INDEX(Anual!$A$2:$A$8,24),""),IF(24<=82,INDEX(Mensual!$A$2:$A$83,24),"")) | B38: =IF($C$10="Sí",H38/H$13*100,H38) | C38: =IF($C$10="Sí",I38/I$13*100,I38) | D38: =IF($C$10="Sí",J38/J$13*100,J38) | E38: =IF($C$10="Sí",K38/K$13*100,K38) | H38: =IF(OR($A38="",H$12=0),NA(),IF($C$9="Anual",IF(INDEX(Anual!$B$2:$J$8,24,H$12)="",NA(),INDEX(Anual!$B$2:$J$8,24,H$12)),IF(INDEX(Mensual!$B$2:$S$83,24,H$12)="",NA(),INDEX(Mensual!$B$2:$S$83,24,H$12)))) | I38: =IF(OR($A38="",I$12=0),NA(),IF($C$9="Anual",IF(INDEX(Anual!$B$2:$J$8,24,I$12)="",NA(),INDEX(Anual!$B$2:$J$8,24,I$12)),IF(INDEX(Mensual!$B$2:$S$83,24,I$12)="",NA(),INDEX(Mensual!$B$2:$S$83,24,I$12)))) | J38: =IF(OR($A38="",J$12=0),NA(),IF($C$9="Anual",IF(INDEX(Anual!$B$2:$J$8,24,J$12)="",NA(),INDEX(Anual!$B$2:$J$8,24,J$12)),IF(INDEX(Mensual!$B$2:$S$83,24,J$12)="",NA(),INDEX(Mensual!$B$2:$S$83,24,J$12)))) | K38: =IF(OR($A38="",K$12=0),NA(),IF($C$9="Anual",IF(INDEX(Anual!$B$2:$J$8,24,K$12)="",NA(),INDEX(Anual!$B$2:$J$8,24,K$12)),IF(INDEX(Mensual!$B$2:$S$83,24,K$12)="",NA(),INDEX(Mensual!$B$2:$S$83,24,K$12))))
A39: =IF($C$9="Anual",IF(25<=7,INDEX(Anual!$A$2:$A$8,25),""),IF(25<=82,INDEX(Mensual!$A$2:$A$83,25),"")) | B39: =IF($C$10="Sí",H39/H$13*100,H39) | C39: =IF($C$10="Sí",I39/I$13*100,I39) | D39: =IF($C$10="Sí",J39/J$13*100,J39) | E39: =IF($C$10="Sí",K39/K$13*100,K39) | H39: =IF(OR($A39="",H$12=0),NA(),IF($C$9="Anual",IF(INDEX(Anual!$B$2:$J$8,25,H$12)="",NA(),INDEX(Anual!$B$2:$J$8,25,H$12)),IF(INDEX(Mensual!$B$2:$S$83,25,H$12)="",NA(),INDEX(Mensual!$B$2:$S$83,25,H$12)))) | I39: =IF(OR($A39="",I$12=0),NA(),IF($C$9="Anual",IF(INDEX(Anual!$B$2:$J$8,25,I$12)="",NA(),INDEX(Anual!$B$2:$J$8,25,I$12)),IF(INDEX(Mensual!$B$2:$S$83,25,I$12)="",NA(),INDEX(Mensual!$B$2:$S$83,25,I$12)))) | J39: =IF(OR($A39="",J$12=0),NA(),IF($C$9="Anual",IF(INDEX(Anual!$B$2:$J$8,25,J$12)="",NA(),INDEX(Anual!$B$2:$J$8,25,J$12)),IF(INDEX(Mensual!$B$2:$S$83,25,J$12)="",NA(),INDEX(Mensual!$B$2:$S$83,25,J$12)))) | K39: =IF(OR($A39="",K$12=0),NA(),IF($C$9="Anual",IF(INDEX(Anual!$B$2:$J$8,25,K$12)="",NA(),INDEX(Anual!$B$2:$J$8,25,K$12)),IF(INDEX(Mensual!$B$2:$S$83,25,K$12)="",NA(),INDEX(Mensual!$B$2:$S$83,25,K$12))))
A40: =IF($C$9="Anual",IF(26<=7,INDEX(Anual!$A$2:$A$8,26),""),IF(26<=82,INDEX(Mensual!$A$2:$A$83,26),"")) | B40: =IF($C$10="Sí",H40/H$13*100,H40) | C40: =IF($C$10="Sí",I40/I$13*100,I40) | D40: =IF($C$10="Sí",J40/J$13*100,J40) | E40: =IF($C$10="Sí",K40/K$13*100,K40) | H40: =IF(OR($A40="",H$12=0),NA(),IF($C$9="Anual",IF(INDEX(Anual!$B$2:$J$8,26,H$12)="",NA(),INDEX(Anual!$B$2:$J$8,26,H$12)),IF(INDEX(Mensual!$B$2:$S$83,26,H$12)="",NA(),INDEX(Mensual!$B$2:$S$83,26,H$12)))) | I40: =IF(OR($A40="",I$12=0),NA(),IF($C$9="Anual",IF(INDEX(Anual!$B$2:$J$8,26,I$12)="",NA(),INDEX(Anual!$B$2:$J$8,26,I$12)),IF(INDEX(Mensual!$B$2:$S$83,26,I$12)="",NA(),INDEX(Mensual!$B$2:$S$83,26,I$12)))) | J40: =IF(OR($A40="",J$12=0),NA(),IF($C$9="Anual",IF(INDEX(Anual!$B$2:$J$8,26,J$12)="",NA(),INDEX(Anual!$B$2:$J$8,26,J$12)),IF(INDEX(Mensual!$B$2:$S$83,26,J$12)="",NA(),INDEX(Mensual!$B$2:$S$83,26,J$12)))) | K40: =IF(OR($A40="",K$12=0),NA(),IF($C$9="Anual",IF(INDEX(Anual!$B$2:$J$8,26,K$12)="",NA(),INDEX(Anual!$B$2:$J$8,26,K$12)),IF(INDEX(Mensual!$B$2:$S$83,26,K$12)="",NA(),INDEX(Mensual!$B$2:$S$83,26,K$12))))
A41: =IF($C$9="Anual",IF(27<=7,INDEX(Anual!$A$2:$A$8,27),""),IF(27<=82,INDEX(Mensual!$A$2:$A$83,27),"")) | B41: =IF($C$10="Sí",H41/H$13*100,H41) | C41: =IF($C$10="Sí",I41/I$13*100,I41) | D41: =IF($C$10="Sí",J41/J$13*100,J41) | E41: =IF($C$10="Sí",K41/K$13*100,K41) | H41: =IF(OR($A41="",H$12=0),NA(),IF($C$9="Anual",IF(INDEX(Anual!$B$2:$J$8,27,H$12)="",NA(),INDEX(Anual!$B$2:$J$8,27,H$12)),IF(INDEX(Mensual!$B$2:$S$83,27,H$12)="",NA(),INDEX(Mensual!$B$2:$S$83,27,H$12)))) | I41: =IF(OR($A41="",I$12=0),NA(),IF($C$9="Anual",IF(INDEX(Anual!$B$2:$J$8,27,I$12)="",NA(),INDEX(Anual!$B$2:$J$8,27,I$12)),IF(INDEX(Mensual!$B$2:$S$83,27,I$12)="",NA(),INDEX(Mensual!$B$2:$S$83,27,I$12)))) | J41: =IF(OR($A41="",J$12=0),NA(),IF($C$9="Anual",IF(INDEX(Anual!$B$2:$J$8,27,J$12)="",NA(),INDEX(Anual!$B$2:$J$8,27,J$12)),IF(INDEX(Mensual!$B$2:$S$83,27,J$12)="",NA(),INDEX(Mensual!$B$2:$S$83,27,J$12)))) | K41: =IF(OR($A41="",K$12=0),NA(),IF($C$9="Anual",IF(INDEX(Anual!$B$2:$J$8,27,K$12)="",NA(),INDEX(Anual!$B$2:$J$8,27,K$12)),IF(INDEX(Mensual!$B$2:$S$83,27,K$12)="",NA(),INDEX(Mensual!$B$2:$S$83,27,K$12))))
...

Sheet Datos 1 OMIE
A1: 1. Electricidad: precio del mercado diario OMIE, España
A2: Fuente: OMIE, ficheros marginalpdbc (precio marginal del mercado diario). Unidad original: €/MWh. Frecuencia: diaria (media aritmética de los periodos horarios o cuarto-horarios del día). Impuestos del dato original: sin impuestos (precio mayorista). Conversión: €/MWh ÷ 1.000 = €/kWh
A4: Fecha | B4: Periodo | C4: Valor original | D4: Unidad | E4: €/kWh sin impuestos | F4: €/kWh con impuestos | G4: Origen del precio con impuestos | H4: Impuestos aplicados | I4: Pendiente | J4: Fecha de publicación | K4: Referencia (fichero / BOE / PDF) | L4: Nota
A5: 43831 | B5: 2020-01-01 | C5: 35.5404 | D5: €/MWh | E5: 0.03554 | G5: no aplica (precio mayorista) | J5: 2019-12-31 | K5: marginalpdbc_20200101.1 | L5: 24 periodos; mín 30.00, máx 46.16 €/MWh
A6: 43832 | B6: 2020-01-02 | C6: 39.995 | D6: €/MWh | E6: 0.039995 | G6: no aplica (precio mayorista) | J6: 2020-01-01 | K6: marginalpdbc_20200102.1 | L6: 24 periodos; mín 28.42, máx 46.72 €/MWh
A7: 43833 | B7: 2020-01-03 | C7: 39.5063 | D7: €/MWh | E7: 0.039506 | G7: no aplica (precio mayorista) | J7: 2020-01-02 | K7: marginalpdbc_20200103.1 | L7: 24 periodos; mín 29.74, máx 47.23 €/MWh
A8: 43834 | B8: 2020-01-04 | C8: 35.6708 | D8: €/MWh | E8: 0.035671 | G8: no aplica (precio mayorista) | J8: 2020-01-03 | K8: marginalpdbc_20200104.1 | L8: 24 periodos; mín 29.84, máx 44.44 €/MWh
A9: 43835 | B9: 2020-01-05 | C9: 38.1754 | D9: €/MWh | E9: 0.038175 | G9: no aplica (precio mayorista) | J9: 2020-01-04 | K9: marginalpdbc_20200105.1 | L9: 24 periodos; mín 29.88, máx 53.29 €/MWh
A10: 43836 | B10: 2020-01-06 | C10: 42.1662 | D10: €/MWh | E10: 0.042166 | G10: no aplica (precio mayorista) | J10: 2020-01-05 | K10: marginalpdbc_20200106.1 | L10: 24 periodos; mín 31.50, máx 49.01 €/MWh
A11: 43837 | B11: 2020-01-07 | C11: 47.0125 | D11: €/MWh | E11: 0.047012 | G11: no aplica (precio mayorista) | J11: 2020-01-06 | K11: marginalpdbc_20200107.1 | L11: 24 periodos; mín 33.01, máx 56.26 €/MWh
A12: 43838 | B12: 2020-01-08 | C12: 46.8062 | D12: €/MWh | E12: 0.046806 | G12: no aplica (precio mayorista) | J12: 2020-01-07 | K12: marginalpdbc_20200108.1 | L12: 24 periodos; mín 33.07, máx 55.92 €/MWh
A13: 43839 | B13: 2020-01-09 | C13: 44.2058 | D13: €/MWh | E13: 0.044206 | G13: no aplica (precio mayorista) | J13: 2020-01-08 | K13: marginalpdbc_20200109.1 | L13: 24 periodos; mín 33.56, máx 53.31 €/MWh
A14: 43840 | B14: 2020-01-10 | C14: 40.5692 | D14: €/MWh | E14: 0.040569 | G14: no aplica (precio mayorista) | J14: 2020-01-09 | K14: marginalpdbc_20200110.1 | L14: 24 periodos; mín 27.65, máx 50.85 €/MWh
A15: 43841 | B15: 2020-01-11 | C15: 41.8392 | D15: €/MWh | E15: 0.041839 | G15: no aplica (precio mayorista) | J15: 2020-01-10 | K15: marginalpdbc_20200111.1 | L15: 24 periodos; mín 34.13, máx 56.26 €/MWh
A16: 43842 | B16: 2020-01-12 | C16: 42.3596 | D16: €/MWh | E16: 0.04236 | G16: no aplica (precio mayorista) | J16: 2020-01-11 | K16: marginalpdbc_20200112.1 | L16: 24 periodos; mín 37.03, máx 55.98 €/MWh
... A2493: 46322 | B2493: 2026-10-27 | C2493: 206.8894 | D2493: €/MWh | E2493: 0.206889 | G2493: no aplica (precio mayorista) | J2493: 2026-10-26 | K2493: marginalpdbc_20261027.1 | L2493: 96 periodos; mín 100.00, máx 290.00 €/MWh

Sheet Datos 2 MIBGAS
A1: 2. Gas natural: MIBGAS-ES Index
A2: Fuente: MIBGAS, fichero anual MIBGAS_Data (hoja de índices), MIBGAS-ES Index. Unidad original: €/MWh. Frecuencia: diaria (por día de gas). Impuestos del dato original: sin impuestos (precio mayorista). Conversión: €/MWh ÷ 1.000 = €/kWh (el índice se expresa sobre PCS, como todo el mercado gasista)
A4: Fecha | B4: Periodo | C4: Valor original | D4: Unidad | E4: €/kWh sin impuestos | F4: €/kWh con impuestos | G4: Origen del precio con impuestos | H4: Impuestos aplicados | I4: Pendiente | J4: Fecha de publicación | K4: Referencia (fichero / BOE / PDF) | L4: Nota
A5: 43831 | B5: 2020-01-01 | C5: 11.27 | D5: €/MWh | E5: 0.01127 | G5: no aplica (precio mayorista) | J5: 2020-01-01 | K5: MIBGAS_Data_2020.xlsx | L5: volumen 91328 MWh
A6: 43832 | B6: 2020-01-02 | C6: 11.61 | D6: €/MWh | E6: 0.01161 | G6: no aplica (precio mayorista) | J6: 2020-01-02 | K6: MIBGAS_Data_2020.xlsx | L6: volumen 79149 MWh
A7: 43833 | B7: 2020-01-03 | C7: 11.68 | D7: €/MWh | E7: 0.01168 | G7: no aplica (precio mayorista) | J7: 2020-01-03 | K7: MIBGAS_Data_2020.xlsx | L7: volumen 95254 MWh
A8: 43834 | B8: 2020-01-04 | C8: 11.77 | D8: €/MWh | E8: 0.01177 | G8: no aplica (precio mayorista) | J8: 2020-01-04 | K8: MIBGAS_Data_2020.xlsx | L8: volumen 95479 MWh
A9: 43835 | B9: 2020-01-05 | C9: 11.77 | D9: €/MWh | E9: 0.01177 | G9: no aplica (precio mayorista) | J9: 2020-01-05 | K9: MIBGAS_Data_2020.xlsx | L9: volumen 97181 MWh
A10: 43836 | B10: 2020-01-06 | C10: 11.99 | D10: €/MWh | E10: 0.01199 | G10: no aplica (precio mayorista) | J10: 2020-01-06 | K10: MIBGAS_Data_2020.xlsx | L10: volumen 92656 MWh
A11: 43837 | B11: 2020-01-07 | C11: 13.34 | D11: €/MWh | E11: 0.01334 | G11: no aplica (precio mayorista) | J11: 2020-01-07 | K11: MIBGAS_Data_2020.xlsx | L11: volumen 101084 MWh
A12: 43838 | B12: 2020-01-08 | C12: 14.48 | D12: €/MWh | E12: 0.01448 | G12: no aplica (precio mayorista) | J12: 2020-01-08 | K12: MIBGAS_Data_2020.xlsx | L12: volumen 148954 MWh
A13: 43839 | B13: 2020-01-09 | C13: 13.56 | D13: €/MWh | E13: 0.01356 | G13: no aplica (precio mayorista) | J13: 2020-01-09 | K13: MIBGAS_Data_2020.xlsx | L13: volumen 142949 MWh
A14: 43840 | B14: 2020-01-10 | C14: 12.15 | D14: €/MWh | E14: 0.01215 | G14: no aplica (precio mayorista) | J14: 2020-01-10 | K14: MIBGAS_Data_2020.xlsx | L14: volumen 64454 MWh
A15: 43841 | B15: 2020-01-11 | C15: 11.61 | D15: €/MWh | E15: 0.01161 | G15: no aplica (precio mayorista) | J15: 2020-01-11 | K15: MIBGAS_Data_2020.xlsx | L15: volumen 46540 MWh
A16: 43842 | B16: 2020-01-12 | C16: 11.87 | D16: €/MWh | E16: 0.01187 | G16: no aplica (precio mayorista) | J16: 2020-01-12 | K16: MIBGAS_Data_2020.xlsx | L16: volumen 53278 MWh
... A1100: 44926 | B1100: 2022-12-31 | C1100: 57.91 | D1100: €/MWh | E1100: 0.05791 | G1100: no aplica (precio mayorista) | J1100: 2022-12-31 | K1100: MIBGAS_Data_2022.xlsx | L1100: volumen 265020 MWh
A1101: 44927 | B1101: 2023-01-01 | C1101: 59.42 | D1101: €/MWh | E1101: 0.05942 | G1101: no aplica (precio mayorista) | J1101: 2023-01-01 | K1101: MIBGAS_Data_2023.xlsx
A1102: 44928 | B1102: 2023-01-02 | C1102: 62.71 | D1102: €/MWh | E1102: 0.06271 | G1102: no aplica (precio mayorista) | J1102: 2023-01-02 | K1102: MIBGAS_Data_2023.xlsx
A1103: 44929 | B1103: 2023-01-03 | C1103: 67 | D1103: €/MWh | E1103: 0.067 | G1103: no aplica (precio mayorista) | J1103: 2023-01-03 | K1103: MIBGAS_Data_2023.xlsx
A1104: 44930 | B1104: 2023-01-04 | C1104: 64.91 | D1104: €/MWh | E1104: 0.06491 | G1104: no aplica (precio mayorista) | J1104: 2023-01-04 | K1104: MIBGAS_Data_2023.xlsx
A1105: 44931 | B1105: 2023-01-05 | C1105: 58.74 | D1105: €/MWh | E1105: 0.05874 | G1105: no aplica (precio mayorista) | J1105: 2023-01-05 | K1105: MIBGAS_Data_2023.xlsx
A1106: 44932 | B1106: 2023-01-06 | C1106: 59.74 | D1106: €/MWh | E1106: 0.05974 | G1106: no aplica (precio mayorista) | J1106: 2023-01-06 | K1106: MIBGAS_Data_2023.xlsx
A1107: 44933 | B1107: 2023-01-07 | C1107: 60.69 | D1107: €/MWh | E1107: 0.06069 | G1107: no aplica (precio mayorista) | J1107: 2023-01-07 | K1107: MIBGAS_Data_2023.xlsx
A1108: 44934 | B1108: 2023-01-08 | C1108: 61.28 | D1108: €/MWh | E1108: 0.06128 | G1108: no aplica (precio mayorista) | J1108: 2023-01-08 | K1108: MIBGAS_Data_2023.xlsx
A1109: 44935 | B1109: 2023-01-09 | C1109: 63.09 | D1109: €/MWh | E1109: 0.06309 | G1109: no aplica (precio mayorista) | J1109: 2023-01-09 | K1109: MIBGAS_Data_2023.xlsx
A1110: 44936 | B1110: 2023-01-10 | C1110: 66.33 | D1110: €/MWh | E1110: 0.06633 | G1110: no aplica (precio mayorista) | J1110: 2023-01-10 | K1110: MIBGAS_Data_2023.xlsx
A1111: 44937 | B1111: 2023-01-11 | C1111: 64.67 | D1111: €/MWh | E1111: 0.06467 | G1111: no aplica (precio mayorista) | J1111: 2023-01-11 | K1111: MIBGAS_Data_2023.xlsx
A1112: 44938 | B1112: 2023-01-12 | C1112: 62.28 | D1112: €/MWh | E1112: 0.06228 | G1112: no aplica (precio mayorista) | J1112: 2023-01-12 | K1112: MIBGAS_Data_2023.xlsx
... A2495: 46321 | B2495: 2026-10-26 | C2495: 94.69 | D2495: €/MWh | E2495: 0.09469 | G2495: no aplica (precio mayorista) | J2495: 2026-10-26 | K2495: MIBGAS_Data_2026.xlsx

Sheet Datos 3 Gasóleo A
A1: 3. Gasóleo de automoción: precio medio en España
A2: Fuente: Comisión Europea, Weekly Oil Bulletin (fichero histórico de precios). Unidad original: €/l. Frecuencia: semanal (precio del lunes). Impuestos del dato original: con impuestos (y también sin impuestos). Conversión: €/l ÷ 10.28 kWh/l (PCI; decisión 10)
A4: Fecha | B4: Periodo | C4: Valor original | D4: Unidad | E4: €/kWh sin impuestos | F4: €/kWh con impuestos | G4: Origen del precio con impuestos | H4: Impuestos aplicados | I4: Pendiente | J4: Fecha de publicación | K4: Referencia (fichero / BOE / PDF) | L4: Nota
A5: 43836 | B5: 2020-01-06 | C5: 1.24707 | D5: €/l | E5: 0.063389 | F5: 0.12131 | G5: original (el Boletín publica con y sin impuestos) | H5: IVA e impuesto sobre hidrocarburos incluidos por la fuente | K5: Weekly_Oil_Bulletin_Prices_History_maticni_4web.xlsx
A6: 43843 | B6: 2020-01-13 | C6: 1.25395 | D6: €/l | E6: 0.063942 | F6: 0.12198 | G6: original (el Boletín publica con y sin impuestos) | H6: IVA e impuesto sobre hidrocarburos incluidos por la fuente | K6: Weekly_Oil_Bulletin_Prices_History_maticni_4web.xlsx
A7: 43850 | B7: 2020-01-20 | C7: 1.24658 | D7: €/l | E7: 0.063349 | F7: 0.121263 | G7: original (el Boletín publica con y sin impuestos) | H7: IVA e impuesto sobre hidrocarburos incluidos por la fuente | K7: Weekly_Oil_Bulletin_Prices_History_maticni_4web.xlsx
A8: 43857 | B8: 2020-01-27 | C8: 1.23597 | D8: €/l | E8: 0.062496 | F8: 0.120231 | G8: original (el Boletín publica con y sin impuestos) | H8: IVA e impuesto sobre hidrocarburos incluidos por la fuente | K8: Weekly_Oil_Bulletin_Prices_History_maticni_4web.xlsx
A9: 43864 | B9: 2020-02-03 | C9: 1.2214 | D9: €/l | E9: 0.061325 | F9: 0.118813 | G9: original (el Boletín publica con y sin impuestos) | H9: IVA e impuesto sobre hidrocarburos incluidos por la fuente | K9: Weekly_Oil_Bulletin_Prices_History_maticni_4web.xlsx
A10: 43871 | B10: 2020-02-10 | C10: 1.20624 | D10: €/l | E10: 0.060106 | F10: 0.117339 | G10: original (el Boletín publica con y sin impuestos) | H10: IVA e impuesto sobre hidrocarburos incluidos por la fuente | K10: Weekly_Oil_Bulletin_Prices_History_maticni_4web.xlsx
A11: 43878 | B11: 2020-02-17 | C11: 1.20035 | D11: €/l | E11: 0.059632 | F11: 0.116766 | G11: original (el Boletín publica con y sin impuestos) | H11: IVA e impuesto sobre hidrocarburos incluidos por la fuente | K11: Weekly_Oil_Bulletin_Prices_History_maticni_4web.xlsx
A12: 43885 | B12: 2020-02-24 | C12: 1.20155 | D12: €/l | E12: 0.05973 | F12: 0.116882 | G12: original (el Boletín publica con y sin impuestos) | H12: IVA e impuesto sobre hidrocarburos incluidos por la fuente | K12: Weekly_Oil_Bulletin_Prices_History_maticni_4web.xlsx
A13: 43892 | B13: 2020-03-02 | C13: 1.19006 | D13: €/l | E13: 0.058805 | F13: 0.115765 | G13: original (el Boletín publica con y sin impuestos) | H13: IVA e impuesto sobre hidrocarburos incluidos por la fuente | K13: Weekly_Oil_Bulletin_Prices_History_maticni_4web.xlsx
A14: 43899 | B14: 2020-03-09 | C14: 1.17108 | D14: €/l | E14: 0.057279 | F14: 0.113918 | G14: original (el Boletín publica con y sin impuestos) | H14: IVA e impuesto sobre hidrocarburos incluidos por la fuente | K14: Weekly_Oil_Bulletin_Prices_History_maticni_4web.xlsx
A15: 43906 | B15: 2020-03-16 | C15: 1.1278 | D15: €/l | E15: 0.053801 | F15: 0.109708 | G15: original (el Boletín publica con y sin impuestos) | H15: IVA e impuesto sobre hidrocarburos incluidos por la fuente | K15: Weekly_Oil_Bulletin_Prices_History_maticni_4web.xlsx
A16: 43913 | B16: 2020-03-23 | C16: 1.08489 | D16: €/l | E16: 0.05035 | F16: 0.105534 | G16: original (el Boletín publica con y sin impuestos) | H16: IVA e impuesto sobre hidrocarburos incluidos por la fuente | K16: Weekly_Oil_Bulletin_Prices_History_maticni_4web.xlsx
... A116: 44648 | B116: 2022-03-28 | C116: 1.83719 | D116: €/l | E116: 0.110831 | F116: 0.178715 | G116: original (el Boletín publica con y sin impuestos) | H116: IVA e impuesto sobre hidrocarburos incluidos por la fuente | K116: Weekly_Oil_Bulletin_Prices_History_maticni_4web.xlsx
A117: 44655 | B117: 2022-04-04 | C117: 1.84703 | D117: €/l | E117: 0.111622 | F117: 0.179672 | G117: original (el Boletín publica con y sin impuestos) | H117: IVA e impuesto sobre hidrocarburos incluidos por la fuente | K117: Weekly_Oil_Bulletin_Prices_History_maticni_4web.xlsx | L117: precio antes de la bonificación de 20 c€/l (RDL 6/2022), que el Boletín no descuenta
A118: 44662 | B118: 2022-04-11 | C118: 1.81387 | D118: €/l | E118: 0.108956 | F118: 0.176446 | G118: original (el Boletín publica con y sin impuestos) | H118: IVA e impuesto sobre hidrocarburos incluidos por la fuente | K118: Weekly_Oil_Bulletin_Prices_History_maticni_4web.xlsx | L118: precio antes de la bonificación de 20 c€/l (RDL 6/2022), que el Boletín no descuenta
